Workbook
Name Slicer_Category: #N/A
Name Slicer_Order_Status: #N/A
Name Slicer_Region: #N/A

Sheet Raw_Data
A1: Order ID | B1: Order Date | C1: Customer ID | D1: Customer Name | E1: Region | F1: City | G1: Product | H1: Category | I1: Quantity | J1: Unit Price | K1: Discount % | L1: Payment Method | M1: Order Status | N1: Expected Delivery Date | O1: Actual Delivery Date | P1: Gross Sales | Q1: Discount Amount | R1: Net Sales | S1: Delivery Days | T1: Delivery Status | U1: Month | V1: Month Start | W1: Cancelled Sales
A2: ORD-10001 | B2: 46137 | C2: CUST-1048 | D2: Customer 1112 | E2: South | F2: Bengaluru | G2: Jeans | H2: Fashion | I2: 1 | J2: 1799 | K2: 0 | L2: COD | M2: Delivered | N2: 46143 | O2: 46138 | P2: =Orders[[#This Row],[Quantity]]*Orders[[#This Row],[Unit Price]] -> 1799 | Q2: =Orders[[#This Row],[Gross Sales]]*Orders[[#This Row],[Discount %]] -> 0 | R2: =Orders[[#This Row],[Gross Sales]]-Orders[[#This Row],[Discount Amount]] -> 1799 | S2: =IF(Orders[[#This Row],[Actual Delivery Date]]="","",Orders[[#This Row],[Actual Delivery Date]]-Orders[[#This Row],[Order Date]]) -> 1 | T2: =IF(Orders[[#This Row],[Actual Delivery Date]]="","Pending",IF(Orders[[#This Row],[Actual Delivery Date]]<=Orders[[#This Row],[Expected Delivery Date]],"On Time","Late")) -> On Time | U2: =TEXT(Orders[[#This Row],[Order Date]],"mmm") -> Apr | V2: =DATE(YEAR(Orders[[#This Row],[Order Date]]),MONTH(Orders[[#This Row],[Order Date]]),1) -> 46113 | W2: =IF(Orders[[#This Row],[Order Status]]="Cancelled",Orders[[#This Row],[Net Sales]],0) -> 0
A3: ORD-10002 | B3: 46355 | C3: CUST-1082 | D3: Customer 1217 | E3: West | F3: Mumbai | G3: Resistance Bands | H3: Sports | I3: 2 | J3: 599 | K3: 0.15 | L3: Credit Card | M3: Delivered | N3: 46361 | O3: 46356 | P3: =Orders[[#This Row],[Quantity]]*Orders[[#This Row],[Unit Price]] -> 1198 | Q3: =Orders[[#This Row],[Gross Sales]]*Orders[[#This Row],[Discount %]] -> 179.7 | R3: =Orders[[#This Row],[Gross Sales]]-Orders[[#This Row],[Discount Amount]] -> 1018.3 | S3: =IF(Orders[[#This Row],[Actual Delivery Date]]="","",Orders[[#This Row],[Actual Delivery Date]]-Orders[[#This Row],[Order Date]]) -> 1 | T3: =IF(Orders[[#This Row],[Actual Delivery Date]]="","Pending",IF(Orders[[#This Row],[Actual Delivery Date]]<=Orders[[#This Row],[Expected Delivery Date]],"On Time","Late")) -> On Time | U3: =TEXT(Orders[[#This Row],[Order Date]],"mmm") -> Nov | V3: =DATE(YEAR(Orders[[#This Row],[Order Date]]),MONTH(Orders[[#This Row],[Order Date]]),1) -> 46327 | W3: =IF(Orders[[#This Row],[Order Status]]="Cancelled",Orders[[#This Row],[Net Sales]],0) -> 0
A4: ORD-10003 | B4: 46195 | C4: CUST-1236 | D4: Customer 1275 | E4: North | F4: Lucknow | G4: Water Bottle | H4: Home | I4: 1 | J4: 699 | K4: 0.15 | L4: UPI | M4: Delivered | N4: 46199 | O4: 46196 | P4: =Orders[[#This Row],[Quantity]]*Orders[[#This Row],[Unit Price]] -> 699 | Q4: =Orders[[#This Row],[Gross Sales]]*Orders[[#This Row],[Discount %]] -> 104.85 | R4: =Orders[[#This Row],[Gross Sales]]-Orders[[#This Row],[Discount Amount]] -> 594.15 | S4: =IF(Orders[[#This Row],[Actual Delivery Date]]="","",Orders[[#This Row],[Actual Delivery Date]]-Orders[[#This Row],[Order Date]]) -> 1 | T4: =IF(Orders[[#This Row],[Actual Delivery Date]]="","Pending",IF(Orders[[#This Row],[Actual Delivery Date]]<=Orders[[#This Row],[Expected Delivery Date]],"On Time","Late")) -> On Time | U4: =TEXT(Orders[[#This Row],[Order Date]],"mmm") -> Jun | V4: =DATE(YEAR(Orders[[#This Row],[Order Date]]),MONTH(Orders[[#This Row],[Order Date]]),1) -> 46174 | W4: =IF(Orders[[#This Row],[Order Status]]="Cancelled",Orders[[#This Row],[Net Sales]],0) -> 0
A5: ORD-10004 | B5: 46173 | C5: CUST-1036 | D5: Customer 1024 | E5: South | F5: Kochi | G5: USB-C Hub | H5: Electronics | I5: 3 | J5: 1799 | K5: 0.2 | L5: Debit Card | M5: Pending | N5: 46176 | P5: =Orders[[#This Row],[Quantity]]*Orders[[#This Row],[Unit Price]] -> 5397 | Q5: =Orders[[#This Row],[Gross Sales]]*Orders[[#This Row],[Discount %]] -> 1079.4 | R5: =Orders[[#This Row],[Gross Sales]]-Orders[[#This Row],[Discount Amount]] -> 4317.6 | S5: =IF(Orders[[#This Row],[Actual Delivery Date]]="","",Orders[[#This Row],[Actual Delivery Date]]-Orders[[#This Row],[Order Date]]) | T5: =IF(Orders[[#This Row],[Actual Delivery Date]]="","Pending",IF(Orders[[#This Row],[Actual Delivery Date]]<=Orders[[#This Row],[Expected Delivery Date]],"On Time","Late")) -> Pending | U5: =TEXT(Orders[[#This Row],[Order Date]],"mmm") -> May | V5: =DATE(YEAR(Orders[[#This Row],[Order Date]]),MONTH(Orders[[#This Row],[Order Date]]),1) -> 46143 | W5: =IF(Orders[[#This Row],[Order Status]]="Cancelled",Orders[[#This Row],[Net Sales]],0) -> 0
A6: ORD-10005 | B6: 46074 | C6: CUST-1037 | D6: Customer 1088 | E6: West | F6: Ahmedabad | G6: Keyboard | H6: Electronics | I6: 1 | J6: 1299 | K6: 0.15 | L6: Debit Card | M6: Delivered | N6: 46078 | O6: 46077 | P6: =Orders[[#This Row],[Quantity]]*Orders[[#This Row],[Unit Price]] -> 1299 | Q6: =Orders[[#This Row],[Gross Sales]]*Orders[[#This Row],[Discount %]] -> 194.85 | R6: =Orders[[#This Row],[Gross Sales]]-Orders[[#This Row],[Discount Amount]] -> 1104.15 | S6: =IF(Orders[[#This Row],[Actual Delivery Date]]="","",Orders[[#This Row],[Actual Delivery Date]]-Orders[[#This Row],[Order Date]]) -> 3 | T6: =IF(Orders[[#This Row],[Actual Delivery Date]]="","Pending",IF(Orders[[#This Row],[Actual Delivery Date]]<=Orders[[#This Row],[Expected Delivery Date]],"On Time","Late")) -> On Time | U6: =TEXT(Orders[[#This Row],[Order Date]],"mmm") -> Feb | V6: =DATE(YEAR(Orders[[#This Row],[Order Date]]),MONTH(Orders[[#This Row],[Order Date]]),1) -> 46054 | W6: =IF(Orders[[#This Row],[Order Status]]="Cancelled",Orders[[#This Row],[Net Sales]],0) -> 0
A7: ORD-10006 | B7: 46161 | C7: CUST-1118 | D7: Customer 1017 | E7: West | F7: Pune | G7: Shampoo | H7: Beauty | I7: 5 | J7: 499 | K7: 0.2 | L7: Credit Card | M7: Cancelled | N7: 46165 | O7: 46162 | P7: =Orders[[#This Row],[Quantity]]*Orders[[#This Row],[Unit Price]] -> 2495 | Q7: =Orders[[#This Row],[Gross Sales]]*Orders[[#This Row],[Discount %]] -> 499 | R7: =Orders[[#This Row],[Gross Sales]]-Orders[[#This Row],[Discount Amount]] -> 1996 | S7: =IF(Orders[[#This Row],[Actual Delivery Date]]="","",Orders[[#This Row],[Actual Delivery Date]]-Orders[[#This Row],[Order Date]]) -> 1 | T7: =IF(Orders[[#This Row],[Actual Delivery Date]]="","Pending",IF(Orders[[#This Row],[Actual Delivery Date]]<=Orders[[#This Row],[Expected Delivery Date]],"On Time","Late")) -> On Time | U7: =TEXT(Orders[[#This Row],[Order Date]],"mmm") -> May | V7: =DATE(YEAR(Orders[[#This Row],[Order Date]]),MONTH(Orders[[#This Row],[Order Date]]),1) -> 46143 | W7: =IF(Orders[[#This Row],[Order Status]]="Cancelled",Orders[[#This Row],[Net Sales]],0) -> 1996
A8: ORD-10007 | B8: 46131 | C8: CUST-1235 | D8: Customer 1074 | E8: North | F8: Chandigarh | G8: T-Shirt | H8: Fashion | I8: 4 | J8: 699 | K8: 0.2 | L8: Debit Card | M8: Delivered | N8: 46138 | O8: 46137 | P8: =Orders[[#This Row],[Quantity]]*Orders[[#This Row],[Unit Price]] -> 2796 | Q8: =Orders[[#This Row],[Gross Sales]]*Orders[[#This Row],[Discount %]] -> 559.2 | R8: =Orders[[#This Row],[Gross Sales]]-Orders[[#This Row],[Discount Amount]] -> 2236.8 | S8: =IF(Orders[[#This Row],[Actual Delivery Date]]="","",Orders[[#This Row],[Actual Delivery Date]]-Orders[[#This Row],[Order Date]]) -> 6 | T8: =IF(Orders[[#This Row],[Actual Delivery Date]]="","Pending",IF(Orders[[#This Row],[Actual Delivery Date]]<=Orders[[#This Row],[Expected Delivery Date]],"On Time","Late")) -> On Time | U8: =TEXT(Orders[[#This Row],[Order Date]],"mmm") -> Apr | V8: =DATE(YEAR(Orders[[#This Row],[Order Date]]),MONTH(Orders[[#This Row],[Order Date]]),1) -> 46113 | W8: =IF(Orders[[#This Row],[Order Status]]="Cancelled",Orders[[#This Row],[Net Sales]],0) -> 0
A9: ORD-10008 | B9: 46298 | C9: CUST-1186 | D9: Customer 1113 | E9: North | F9: Jaipur | G9: Coffee Maker | H9: Home | I9: 1 | J9: 3499 | K9: 0.2 | L9: Net Banking | M9: Pending | N9: 46303 | P9: =Orders[[#This Row],[Quantity]]*Orders[[#This Row],[Unit Price]] -> 3499 | Q9: =Orders[[#This Row],[Gross Sales]]*Orders[[#This Row],[Discount %]] -> 699.8 | R9: =Orders[[#This Row],[Gross Sales]]-Orders[[#This Row],[Discount Amount]] -> 2799.2 | S9: =IF(Orders[[#This Row],[Actual Delivery Date]]="","",Orders[[#This Row],[Actual Delivery Date]]-Orders[[#This Row],[Order Date]]) | T9: =IF(Orders[[#This Row],[Actual Delivery Date]]="","Pending",IF(Orders[[#This Row],[Actual Delivery Date]]<=Orders[[#This Row],[Expected Delivery Date]],"On Time","Late")) -> Pending | U9: =TEXT(Orders[[#This Row],[Order Date]],"mmm") -> Oct | V9: =DATE(YEAR(Orders[[#This Row],[Order Date]]),MONTH(Orders[[#This Row],[Order Date]]),1) -> 46296 | W9: =IF(Orders[[#This Row],[Order Status]]="Cancelled",Orders[[#This Row],[Net Sales]],0) -> 0
A10: ORD-10009 | B10: 46079 | C10: CUST-1198 | D10: Customer 1196 | E10: West | F10: Goa | G10: Wireless Mouse | H10: Electronics | I10: 1 | J10: 799 | K10: 0.05 | L10: Net Banking | M10: Pending | N10: 46081 | P10: =Orders[[#This Row],[Quantity]]*Orders[[#This Row],[Unit Price]] -> 799 | Q10: =Orders[[#This Row],[Gross Sales]]*Orders[[#This Row],[Discount %]] -> 39.95 | R10: =Orders[[#This Row],[Gross Sales]]-Orders[[#This Row],[Discount Amount]] -> 759.05 | S10: =IF(Orders[[#This Row],[Actual Delivery Date]]="","",Orders[[#This Row],[Actual Delivery Date]]-Orders[[#This Row],[Order Date]]) | T10: =IF(Orders[[#This Row],[Actual Delivery Date]]="","Pending",IF(Orders[[#This Row],[Actual Delivery Date]]<=Orders[[#This Row],[Expected Delivery Date]],"On Time","Late")) -> Pending | U10: =TEXT(Orders[[#This Row],[Order Date]],"mmm") -> Feb | V10: =DATE(YEAR(Orders[[#This Row],[Order Date]]),MONTH(Orders[[#This Row],[Order Date]]),1) -> 46054 | W10: =IF(Orders[[#This Row],[Order Status]]="Cancelled",Orders[[#This Row],[Net Sales]],0) -> 0
A11: ORD-10010 | B11: 46371 | C11: CUST-1223 | D11: Customer 1081 | E11: East | F11: Patna | G11: Yoga Mat | H11: Sports | I11: 2 | J11: 899 | K11: 0.2 | L11: Debit Card | M11: Returned | N11: 46378 | O11: 46374 | P11: =Orders[[#This Row],[Quantity]]*Orders[[#This Row],[Unit Price]] -> 1798 | Q11: =Orders[[#This Row],[Gross Sales]]*Orders[[#This Row],[Discount %]] -> 359.6 | R11: =Orders[[#This Row],[Gross Sales]]-Orders[[#This Row],[Discount Amount]] -> 1438.4 | S11: =IF(Orders[[#This Row],[Actual Delivery Date]]="","",Orders[[#This Row],[Actual Delivery Date]]-Orders[[#This Row],[Order Date]]) -> 3 | T11: =IF(Orders[[#This Row],[Actual Delivery Date]]="","Pending",IF(Orders[[#This Row],[Actual Delivery Date]]<=Orders[[#This Row],[Expected Delivery Date]],"On Time","Late")) -> On Time | U11: =TEXT(Orders[[#This Row],[Order Date]],"mmm") -> Dec | V11: =DATE(YEAR(Orders[[#This Row],[Order Date]]),MONTH(Orders[[#This Row],[Order Date]]),1) -> 46357 | W11: =IF(Orders[[#This Row],[Order Status]]="Cancelled",Orders[[#This Row],[Net Sales]],0) -> 0
A12: ORD-10011 | B12: 46114 | C12: CUST-1079 | D12: Customer 1192 | E12: East | F12: Kolkata | G12: Backpack | H12: Fashion | I12: 2 | J12: 1899 | K12: 0 | L12: Debit Card | M12: Returned | N12: 46121 | O12: 46116 | P12: =Orders[[#This Row],[Quantity]]*Orders[[#This Row],[Unit Price]] -> 3798 | Q12: =Orders[[#This Row],[Gross Sales]]*Orders[[#This Row],[Discount %]] -> 0 | R12: =Orders[[#This Row],[Gross Sales]]-Orders[[#This Row],[Discount Amount]] -> 3798 | S12: =IF(Orders[[#This Row],[Actual Delivery Date]]="","",Orders[[#This Row],[Actual Delivery Date]]-Orders[[#This Row],[Order Date]]) -> 2 | T12: =IF(Orders[[#This Row],[Actual Delivery Date]]="","Pending",IF(Orders[[#This Row],[Actual Delivery Date]]<=Orders[[#This Row],[Expected Delivery Date]],"On Time","Late")) -> On Time | U12: =TEXT(Orders[[#This Row],[Order Date]],"mmm") -> Apr | V12: =DATE(YEAR(Orders[[#This Row],[Order Date]]),MONTH(Orders[[#This Row],[Order Date]]),1) -> 46113 | W12: =IF(Orders[[#This Row],[Order Status]]="Cancelled",Orders[[#This Row],[Net Sales]],0) -> 0
A13: ORD-10012 | B13: 46273 | C13: CUST-1044 | D13: Customer 1249 | E13: West | F13: Mumbai | G13: Running Shoes | H13: Sports | I13: 1 | J13: 3299 | K13: 0.1 | L13: Debit Card | M13: Delivered | N13: 46275 | O13: 46274 | P13: =Orders[[#This Row],[Quantity]]*Orders[[#This Row],[Unit Price]] -> 3299 | Q13: =Orders[[#This Row],[Gross Sales]]*Orders[[#This Row],[Discount %]] -> 329.9 | R13: =Orders[[#This Row],[Gross Sales]]-Orders[[#This Row],[Discount Amount]] -> 2969.1 | S13: =IF(Orders[[#This Row],[Actual Delivery Date]]="","",Orders[[#This Row],[Actual Delivery Date]]-Orders[[#This Row],[Order Date]]) -> 1 | T13: =IF(Orders[[#This Row],[Actual Delivery Date]]="","Pending",IF(Orders[[#This Row],[Actual Delivery Date]]<=Orders[[#This Row],[Expected Delivery Date]],"On Time","Late")) -> On Time | U13: =TEXT(Orders[[#This Row],[Order Date]],"mmm") -> Sep | V13: =DATE(YEAR(Orders[[#This Row],[Order Date]]),MONTH(Orders[[#This Row],[Order Date]]),1) -> 46266 | W13: =IF(Orders[[#This Row],[Order Status]]="Cancelled",Orders[[#This Row],[Net Sales]],0) -> 0
A14: ORD-10013 | B14: 46304 | C14: CUST-1160 | D14: Customer 1205 | E14: South | F14: Chennai | G14: Bedsheet Set | H14: Home | I14: 1 | J14: 1599 | K14: 0.2 | L14: COD | M14: Delivered | N14: 46307 | O14: 46309 | P14: =Orders[[#This Row],[Quantity]]*Orders[[#This Row],[Unit Price]] -> 1599 | Q14: =Orders[[#This Row],[Gross Sales]]*Orders[[#This Row],[Discount %]] -> 319.8 | R14: =Orders[[#This Row],[Gross Sales]]-Orders[[#This Row],[Discount Amount]] -> 1279.2 | S14: =IF(Orders[[#This Row],[Actual Delivery Date]]="","",Orders[[#This Row],[Actual Delivery Date]]-Orders[[#This Row],[Order Date]]) -> 5 | T14: =IF(Orders[[#This Row],[Actual Delivery Date]]="","Pending",IF(Orders[[#This Row],[Actual Delivery Date]]<=Orders[[#This Row],[Expected Delivery Date]],"On Time","Late")) -> Late | U14: =TEXT(Orders[[#This Row],[Order Date]],"mmm") -> Oct | V14: =DATE(YEAR(Orders[[#This Row],[Order Date]]),MONTH(Orders[[#This Row],[Order Date]]),1) -> 46296 | W14: =IF(Orders[[#This Row],[Order Status]]="Cancelled",Orders[[#This Row],[Net Sales]],0) -> 0
A15: ORD-10014 | B15: 46084 | C15: CUST-1113 | D15: Customer 1004 | E15: North | F15: Chandigarh | G15: Cricket Bat | H15: Sports | I15: 1 | J15: 2499 | K15: 0 | L15: Debit Card | M15: Delivered | N15: 46090 | O15: 46089 | P15: =Orders[[#This Row],[Quantity]]*Orders[[#This Row],[Unit Price]] -> 2499 | Q15: =Orders[[#This Row],[Gross Sales]]*Orders[[#This Row],[Discount %]] -> 0 | R15: =Orders[[#This Row],[Gross Sales]]-Orders[[#This Row],[Discount Amount]] -> 2499 | S15: =IF(Orders[[#This Row],[Actual Delivery Date]]="","",Orders[[#This Row],[Actual Delivery Date]]-Orders[[#This Row],[Order Date]]) -> 5 | T15: =IF(Orders[[#This Row],[Actual Delivery Date]]="","Pending",IF(Orders[[#This Row],[Actual Delivery Date]]<=Orders[[#This Row],[Expected Delivery Date]],"On Time","Late")) -> On Time | U15: =TEXT(Orders[[#This Row],[Order Date]],"mmm") -> Mar | V15: =DATE(YEAR(Orders[[#This Row],[Order Date]]),MONTH(Orders[[#This Row],[Order Date]]),1) -> 46082 | W15: =IF(Orders[[#This Row],[Order Status]]="Cancelled",Orders[[#This Row],[Net Sales]],0) -> 0
A16: ORD-10015 | B16: 46039 | C16: CUST-1277 | D16: Customer 1068 | E16: South | F16: Bengaluru | G16: Desk Lamp | H16: Home | I16: 3 | J16: 999 | K16: 0 | L16: COD | M16: Delivered | N16: 46043 | O16: 46041 | P16: =Orders[[#This Row],[Quantity]]*Orders[[#This Row],[Unit Price]] -> 2997 | Q16: =Orders[[#This Row],[Gross Sales]]*Orders[[#This Row],[Discount %]] -> 0 | R16: =Orders[[#This Row],[Gross Sales]]-Orders[[#This Row],[Discount Amount]] -> 2997 | S16: =IF(Orders[[#This Row],[Actual Delivery Date]]="","",Orders[[#This Row],[Actual Delivery Date]]-Orders[[#This Row],[Order Date]]) -> 2 | T16: =IF(Orders[[#This Row],[Actual Delivery Date]]="","Pending",IF(Orders[[#This Row],[Actual Delivery Date]]<=Orders[[#This Row],[Expected Delivery Date]],"On Time","Late")) -> On Time | U16: =TEXT(Orders[[#This Row],[Order Date]],"mmm") -> Jan | V16: =DATE(YEAR(Orders[[#This Row],[Order Date]]),MONTH(Orders[[#This Row],[Order Date]]),1) -> 46023 | W16: =IF(Orders[[#This Row],[Order Status]]="Cancelled",Orders[[#This Row],[Net Sales]],0) -> 0
A17: ORD-10016 | B17: 46120 | C17: CUST-1051 | D17: Customer 1032 | E17: East | F17: Bhubaneswar | G17: Shampoo | H17: Beauty | I17: 1 | J17: 499 | K17: 0.15 | L17: Debit Card | M17: Delivered | N17: 46125 | O17: 46121 | P17: =Orders[[#This Row],[Quantity]]*Orders[[#This Row],[Unit Price]] -> 499 | Q17: =Orders[[#This Row],[Gross Sales]]*Orders[[#This Row],[Discount %]] -> 74.85 | R17: =Orders[[#This Row],[Gross Sales]]-Orders[[#This Row],[Discount Amount]] -> 424.15 | S17: =IF(Orders[[#This Row],[Actual Delivery Date]]="","",Orders[[#This Row],[Actual Delivery Date]]-Orders[[#This Row],[Order Date]]) -> 1 | T17: =IF(Orders[[#This Row],[Actual Delivery Date]]="","Pending",IF(Orders[[#This Row],[Actual Delivery Date]]<=Orders[[#This Row],[Expected Delivery Date]],"On Time","Late")) -> On Time | U17: =TEXT(Orders[[#This Row],[Order Date]],"mmm") -> Apr | V17: =DATE(YEAR(Orders[[#This Row],[Order Date]]),MONTH(Orders[[#This Row],[Order Date]]),1) -> 46113 | W17: =IF(Orders[[#This Row],[Order Status]]="Cancelled",Orders[[#This Row],[Net Sales]],0) -> 0
A18: ORD-10017 | B18: 46121 | C18: CUST-1039 | D18: Customer 1227 | E18: East | F18: Patna | G18: Keyboard | H18: Electronics | I18: 1 | J18: 1299 | K18: 0.15 | L18: Credit Card | M18: Delivered | N18: 46124 | O18: 46122 | P18: =Orders[[#This Row],[Quantity]]*Orders[[#This Row],[Unit Price]] -> 1299 | Q18: =Orders[[#This Row],[Gross Sales]]*Orders[[#This Row],[Discount %]] -> 194.85 | R18: =Orders[[#This Row],[Gross Sales]]-Orders[[#This Row],[Discount Amount]] -> 1104.15 | S18: =IF(Orders[[#This Row],[Actual Delivery Date]]="","",Orders[[#This Row],[Actual Delivery Date]]-Orders[[#This Row],[Order Date]]) -> 1 | T18: =IF(Orders[[#This Row],[Actual Delivery Date]]="","Pending",IF(Orders[[#This Row],[Actual Delivery Date]]<=Orders[[#This Row],[Expected Delivery Date]],"On Time","Late")) -> On Time | U18: =TEXT(Orders[[#This Row],[Order Date]],"mmm") -> Apr | V18: =DATE(YEAR(Orders[[#This Row],[Order Date]]),MONTH(Orders[[#This Row],[Order Date]]),1) -> 46113 | W18: =IF(Orders[[#This Row],[Order Status]]="Cancelled",Orders[[#This Row],[Net Sales]],0) -> 0
A19: ORD-10018 | B19: 46070 | C19: CUST-1031 | D19: Customer 1085 | E19: South | F19: Bengaluru | G19: Yoga Mat | H19: Sports | I19: 4 | J19: 899 | K19: 0.05 | L19: Credit Card | M19: Delivered | N19: 46075 | O19: 46074 | P19: =Orders[[#This Row],[Quantity]]*Orders[[#This Row],[Unit Price]] -> 3596 | Q19: =Orders[[#This Row],[Gross Sales]]*Orders[[#This Row],[Discount %]] -> 179.8 | R19: =Orders[[#This Row],[Gross Sales]]-Orders[[#This Row],[Discount Amount]] -> 3416.2 | S19: =IF(Orders[[#This Row],[Actual Delivery Date]]="","",Orders[[#This Row],[Actual Delivery Date]]-Orders[[#This Row],[Order Date]]) -> 4 | T19: =IF(Orders[[#This Row],[Actual Delivery Date]]="","Pending",IF(Orders[[#This Row],[Actual Delivery Date]]<=Orders[[#This Row],[Expected Delivery Date]],"On Time","Late")) -> On Time | U19: =TEXT(Orders[[#This Row],[Order Date]],"mmm") -> Feb | V19: =DATE(YEAR(Orders[[#This Row],[Order Date]]),MONTH(Orders[[#This Row],[Order Date]]),1) -> 46054 | W19: =IF(Orders[[#This Row],[Order Status]]="Cancelled",Orders[[#This Row],[Net Sales]],0) -> 0
A20: ORD-10019 | B20: 46255 | C20: CUST-1297 | D20: Customer 1278 | E20: East | F20: Kolkata | G20: Sunscreen | H20: Beauty | I20: 1 | J20: 749 | K20: 0.2 | L20: Net Banking | M20: Delivered | N20: 46258 | O20: 46256 | P20: =Orders[[#This Row],[Quantity]]*Orders[[#This Row],[Unit Price]] -> 749 | Q20: =Orders[[#This Row],[Gross Sales]]*Orders[[#This Row],[Discount %]] -> 149.8 | R20: =Orders[[#This Row],[Gross Sales]]-Orders[[#This Row],[Discount Amount]] -> 599.2 | S20: =IF(Orders[[#This Row],[Actual Delivery Date]]="","",Orders[[#This Row],[Actual Delivery Date]]-Orders[[#This Row],[Order Date]]) -> 1 | T20: =IF(Orders[[#This Row],[Actual Delivery Date]]="","Pending",IF(Orders[[#This Row],[Actual Delivery Date]]<=Orders[[#This Row],[Expected Delivery Date]],"On Time","Late")) -> On Time | U20: =TEXT(Orders[[#This Row],[Order Date]],"mmm") -> Aug | V20: =DATE(YEAR(Orders[[#This Row],[Order Date]]),MONTH(Orders[[#This Row],[Order Date]]),1) -> 46235 | W20: =IF(Orders[[#This Row],[Order Status]]="Cancelled",Orders[[#This Row],[Net Sales]],0) -> 0
A21: ORD-10020 | B21: 46322 | C21: CUST-1036 | D21: Customer 1035 | E21: South | F21: Hyderabad | G21: Wireless Mouse | H21: Electronics | I21: 2 | J21: 799 | K21: 0.2 | L21: Credit Card | M21: Delivered | N21: 46328 | O21: 46324 | P21: =Orders[[#This Row],[Quantity]]*Orders[[#This Row],[Unit Price]] -> 1598 | Q21: =Orders[[#This Row],[Gross Sales]]*Orders[[#This Row],[Discount %]] -> 319.6 | R21: =Orders[[#This Row],[Gross Sales]]-Orders[[#This Row],[Discount Amount]] -> 1278.4 | S21: =IF(Orders[[#This Row],[Actual Delivery Date]]="","",Orders[[#This Row],[Actual Delivery Date]]-Orders[[#This Row],[Order Date]]) -> 2 | T21: =IF(Orders[[#This Row],[Actual Delivery Date]]="","Pending",IF(Orders[[#This Row],[Actual Delivery Date]]<=Orders[[#This Row],[Expected Delivery Date]],"On Time","Late")) -> On Time | U21: =TEXT(Orders[[#This Row],[Order Date]],"mmm") -> Oct | V21: =DATE(YEAR(Orders[[#This Row],[Order Date]]),MONTH(Orders[[#This Row],[Order Date]]),1) -> 46296 | W21: =IF(Orders[[#This Row],[Order Status]]="Cancelled",Orders[[#This Row],[Net Sales]],0) -> 0
A22: ORD-10021 | B22: 46149 | C22: CUST-1268 | D22: Customer 1162 | E22: West | F22: Goa | G22: USB-C Hub | H22: Electronics | I22: 2 | J22: 1799 | K22: 0 | L22: COD | M22: Delivered | N22: 46154 | O22: 46154 | P22: =Orders[[#This Row],[Quantity]]*Orders[[#This Row],[Unit Price]] -> 3598 | Q22: =Orders[[#This Row],[Gross Sales]]*Orders[[#This Row],[Discount %]] -> 0 | R22: =Orders[[#This Row],[Gross Sales]]-Orders[[#This Row],[Discount Amount]] -> 3598 | S22: =IF(Orders[[#This Row],[Actual Delivery Date]]="","",Orders[[#This Row],[Actual Delivery Date]]-Orders[[#This Row],[Order Date]]) -> 5 | T22: =IF(Orders[[#This Row],[Actual Delivery Date]]="","Pending",IF(Orders[[#This Row],[Actual Delivery Date]]<=Orders[[#This Row],[Expected Delivery Date]],"On Time","Late")) -> On Time | U22: =TEXT(Orders[[#This Row],[Order Date]],"mmm") -> May | V22: =DATE(YEAR(Orders[[#This Row],[Order Date]]),MONTH(Orders[[#This Row],[Order Date]]),1) -> 46143 | W22: =IF(Orders[[#This Row],[Order Status]]="Cancelled",Orders[[#This Row],[Net Sales]],0) -> 0
... A31: ORD-10030 | B31: 46202 | C31: CUST-1092 | D31: Customer 1298 | E31: North | F31: Lucknow | G31: Bluetooth Speaker | H31: Electronics | I31: 2 | J31: 1999 | K31: 0.15 | L31: COD | M31: Delivered | N31: 46204 | O31: 46204 | P31: =Orders[[#This Row],[Quantity]]*Orders[[#This Row],[Unit Price]] -> 3998 | Q31: =Orders[[#This Row],[Gross Sales]]*Orders[[#This Row],[Discount %]] -> 599.7 | R31: =Orders[[#This Row],[Gross Sales]]-Orders[[#This Row],[Discount Amount]] -> 3398.3 | S31: =IF(Orders[[#This Row],[Actual Delivery Date]]="","",Orders[[#This Row],[Actual Delivery Date]]-Orders[[#This Row],[Order Date]]) -> 2 | T31: =IF(Orders[[#This Row],[Actual Delivery Date]]="","Pending",IF(Orders[[#This Row],[Actual Delivery Date]]<=Orders[[#This Row],[Expected Delivery Date]],"On Time","Late")) -> On Time | U31: =TEXT(Orders[[#This Row],[Order Date]],"mmm") -> Jun | V31: =DATE(YEAR(Orders[[#This Row],[Order Date]]),MONTH(Orders[[#This Row],[Order Date]]),1) -> 46174 | W31: =IF(Orders[[#This Row],[Order Status]]="Cancelled",Orders[[#This Row],[Net Sales]],0) -> 0
A32: ORD-10031 | B32: 46245 | C32: CUST-1060 | D32: Customer 1198 | E32: North | F32: Delhi | G32: USB-C Hub | H32: Electronics | I32: 1 | J32: 1799 | K32: 0.1 | L32: Net Banking | M32: Pending | N32: 46251 | P32: =Orders[[#This Row],[Quantity]]*Orders[[#This Row],[Unit Price]] -> 1799 | Q32: =Orders[[#This Row],[Gross Sales]]*Orders[[#This Row],[Discount %]] -> 179.9 | R32: =Orders[[#This Row],[Gross Sales]]-Orders[[#This Row],[Discount Amount]] -> 1619.1 | S32: =IF(Orders[[#This Row],[Actual Delivery Date]]="","",Orders[[#This Row],[Actual Delivery Date]]-Orders[[#This Row],[Order Date]]) | T32: =IF(Orders[[#This Row],[Actual Delivery Date]]="","Pending",IF(Orders[[#This Row],[Actual Delivery Date]]<=Orders[[#This Row],[Expected Delivery Date]],"On Time","Late")) -> Pending | U32: =TEXT(Orders[[#This Row],[Order Date]],"mmm") -> Aug | V32: =DATE(YEAR(Orders[[#This Row],[Order Date]]),MONTH(Orders[[#This Row],[Order Date]]),1) -> 46235 | W32: =IF(Orders[[#This Row],[Order Status]]="Cancelled",Orders[[#This Row],[Net Sales]],0) -> 0
A33: ORD-10032 | B33: 46023 | C33: CUST-1161 | D33: Customer 1064 | E33: West | F33: Ahmedabad | G33: Power Bank | H33: Electronics | I33: 2 | J33: 1499 | K33: 0.2 | L33: Credit Card | M33: Delivered | N33: 46028 | O33: 46026 | P33: =Orders[[#This Row],[Quantity]]*Orders[[#This Row],[Unit Price]] -> 2998 | Q33: =Orders[[#This Row],[Gross Sales]]*Orders[[#This Row],[Discount %]] -> 599.6 | R33: =Orders[[#This Row],[Gross Sales]]-Orders[[#This Row],[Discount Amount]] -> 2398.4 | S33: =IF(Orders[[#This Row],[Actual Delivery Date]]="","",Orders[[#This Row],[Actual Delivery Date]]-Orders[[#This Row],[Order Date]]) -> 3 | T33: =IF(Orders[[#This Row],[Actual Delivery Date]]="","Pending",IF(Orders[[#This Row],[Actual Delivery Date]]<=Orders[[#This Row],[Expected Delivery Date]],"On Time","Late")) -> On Time | U33: =TEXT(Orders[[#This Row],[Order Date]],"mmm") -> Jan | V33: =DATE(YEAR(Orders[[#This Row],[Order Date]]),MONTH(Orders[[#This Row],[Order Date]]),1) -> 46023 | W33: =IF(Orders[[#This Row],[Order Status]]="Cancelled",Orders[[#This Row],[Net Sales]],0) -> 0
A34: ORD-10033 | B34: 46229 | C34: CUST-1090 | D34: Customer 1292 | E34: North | F34: Lucknow | G34: Sunscreen | H34: Beauty | I34: 2 | J34: 749 | K34: 0.2 | L34: Credit Card | M34: Delivered | N34: 46234 | O34: 46233 | P34: =Orders[[#This Row],[Quantity]]*Orders[[#This Row],[Unit Price]] -> 1498 | Q34: =Orders[[#This Row],[Gross Sales]]*Orders[[#This Row],[Discount %]] -> 299.6 | R34: =Orders[[#This Row],[Gross Sales]]-Orders[[#This Row],[Discount Amount]] -> 1198.4 | S34: =IF(Orders[[#This Row],[Actual Delivery Date]]="","",Orders[[#This Row],[Actual Delivery Date]]-Orders[[#This Row],[Order Date]]) -> 4 | T34: =IF(Orders[[#This Row],[Actual Delivery Date]]="","Pending",IF(Orders[[#This Row],[Actual Delivery Date]]<=Orders[[#This Row],[Expected Delivery Date]],"On Time","Late")) -> On Time | U34: =TEXT(Orders[[#This Row],[Order Date]],"mmm") -> Jul | V34: =DATE(YEAR(Orders[[#This Row],[Order Date]]),MONTH(Orders[[#This Row],[Order Date]]),1) -> 46204 | W34: =IF(Orders[[#This Row],[Order Status]]="Cancelled",Orders[[#This Row],[Net Sales]],0) -> 0
A35: ORD-10034 | B35: 46178 | C35: CUST-1165 | D35: Customer 1239 | E35: North | F35: Chandigarh | G35: Yoga Mat | H35: Sports | I35: 1 | J35: 899 | K35: 0.15 | L35: COD | M35: Pending | N35: 46185 | P35: =Orders[[#This Row],[Quantity]]*Orders[[#This Row],[Unit Price]] -> 899 | Q35: =Orders[[#This Row],[Gross Sales]]*Orders[[#This Row],[Discount %]] -> 134.85 | R35: =Orders[[#This Row],[Gross Sales]]-Orders[[#This Row],[Discount Amount]] -> 764.15 | S35: =IF(Orders[[#This Row],[Actual Delivery Date]]="","",Orders[[#This Row],[Actual Delivery Date]]-Orders[[#This Row],[Order Date]]) | T35: =IF(Orders[[#This Row],[Actual Delivery Date]]="","Pending",IF(Orders[[#This Row],[Actual Delivery Date]]<=Orders[[#This Row],[Expected Delivery Date]],"On Time","Late")) -> Pending | U35: =TEXT(Orders[[#This Row],[Order Date]],"mmm") -> Jun | V35: =DATE(YEAR(Orders[[#This Row],[Order Date]]),MONTH(Orders[[#This Row],[Order Date]]),1) -> 46174 | W35: =IF(Orders[[#This Row],[Order Status]]="Cancelled",Orders[[#This Row],[Net Sales]],0) -> 0
A36: ORD-10035 | B36: 46265 | C36: CUST-1172 | D36: Customer 1048 | E36: East | F36: Guwahati | G36: Coffee Maker | H36: Home | I36: 3 | J36: 3499 | K36: 0.05 | L36: UPI | M36: Delivered | N36: 46271 | O36: 46270 | P36: =Orders[[#This Row],[Quantity]]*Orders[[#This Row],[Unit Price]] -> 10497 | Q36: =Orders[[#This Row],[Gross Sales]]*Orders[[#This Row],[Discount %]] -> 524.85 | R36: =Orders[[#This Row],[Gross Sales]]-Orders[[#This Row],[Discount Amount]] -> 9972.15 | S36: =IF(Orders[[#This Row],[Actual Delivery Date]]="","",Orders[[#This Row],[Actual Delivery Date]]-Orders[[#This Row],[Order Date]]) -> 5 | T36: =IF(Orders[[#This Row],[Actual Delivery Date]]="","Pending",IF(Orders[[#This Row],[Actual Delivery Date]]<=Orders[[#This Row],[Expected Delivery Date]],"On Time","Late")) -> On Time | U36: =TEXT(Orders[[#This Row],[Order Date]],"mmm") -> Aug | V36: =DATE(YEAR(Orders[[#This Row],[Order Date]]),MONTH(Orders[[#This Row],[Order Date]]),1) -> 46235 | W36: =IF(Orders[[#This Row],[Order Status]]="Cancelled",Orders[[#This Row],[Net Sales]],0) -> 0
A37: ORD-10036 | B37: 46098 | C37: CUST-1234 | D37: Customer 1213 | E37: West | F37: Ahmedabad | G37: Water Bottle | H37: Home | I37: 1 | J37: 699 | K37: 0.05 | L37: Net Banking | M37: Pending | N37: 46100 | P37: =Orders[[#This Row],[Quantity]]*Orders[[#This Row],[Unit Price]] -> 699 | Q37: =Orders[[#This Row],[Gross Sales]]*Orders[[#This Row],[Discount %]] -> 34.95 | R37: =Orders[[#This Row],[Gross Sales]]-Orders[[#This Row],[Discount Amount]] -> 664.05 | S37: =IF(Orders[[#This Row],[Actual Delivery Date]]="","",Orders[[#This Row],[Actual Delivery Date]]-Orders[[#This Row],[Order Date]]) | T37: =IF(Orders[[#This Row],[Actual Delivery Date]]="","Pending",IF(Orders[[#This Row],[Actual Delivery Date]]<=Orders[[#This Row],[Expected Delivery Date]],"On Time","Late")) -> Pending | U37: =TEXT(Orders[[#This Row],[Order Date]],"mmm") -> Mar | V37: =DATE(YEAR(Orders[[#This Row],[Order Date]]),MONTH(Orders[[#This Row],[Order Date]]),1) -> 46082 | W37: =IF(Orders[[#This Row],[Order Status]]="Cancelled",Orders[[#This Row],[Net Sales]],0) -> 0
A38: ORD-10037 | B38: 46147 | C38: CUST-1238 | D38: Customer 1026 | E38: West | F38: Goa | G38: Shampoo | H38: Beauty | I38: 1 | J38: 499 | K38: 0 | L38: UPI | M38: Returned | N38: 46152 | O38: 46152 | P38: =Orders[[#This Row],[Quantity]]*Orders[[#This Row],[Unit Price]] -> 499 | Q38: =Orders[[#This Row],[Gross Sales]]*Orders[[#This Row],[Discount %]] -> 0 | R38: =Orders[[#This Row],[Gross Sales]]-Orders[[#This Row],[Discount Amount]] -> 499 | S38: =IF(Orders[[#This Row],[Actual Delivery Date]]="","",Orders[[#This Row],[Actual Delivery Date]]-Orders[[#This Row],[Order Date]]) -> 5 | T38: =IF(Orders[[#This Row],[Actual Delivery Date]]="","Pending",IF(Orders[[#This Row],[Actual Delivery Date]]<=Orders[[#This Row],[Expected Delivery Date]],"On Time","Late")) -> On Time | U38: =TEXT(Orders[[#This Row],[Order Date]],"mmm") -> May | V38: =DATE(YEAR(Orders[[#This Row],[Order Date]]),MONTH(Orders[[#This Row],[Order Date]]),1) -> 46143 | W38: =IF(Orders[[#This Row],[Order Status]]="Cancelled",Orders[[#This Row],[Net Sales]],0) -> 0
A39: ORD-10038 | B39: 46260 | C39: CUST-1219 | D39: Customer 1281 | E39: West | F39: Mumbai | G39: Moisturizer | H39: Beauty | I39: 2 | J39: 599 | K39: 0.2 | L39: COD | M39: Delivered | N39: 46265 | O39: 46265 | P39: =Orders[[#This Row],[Quantity]]*Orders[[#This Row],[Unit Price]] -> 1198 | Q39: =Orders[[#This Row],[Gross Sales]]*Orders[[#This Row],[Discount %]] -> 239.6 | R39: =Orders[[#This Row],[Gross Sales]]-Orders[[#This Row],[Discount Amount]] -> 958.4 | S39: =IF(Orders[[#This Row],[Actual Delivery Date]]="","",Orders[[#This Row],[Actual Delivery Date]]-Orders[[#This Row],[Order Date]]) -> 5 | T39: =IF(Orders[[#This Row],[Actual Delivery Date]]="","Pending",IF(Orders[[#This Row],[Actual Delivery Date]]<=Orders[[#This Row],[Expected Delivery Date]],"On Time","Late")) -> On Time | U39: =TEXT(Orders[[#This Row],[Order Date]],"mmm") -> Aug | V39: =DATE(YEAR(Orders[[#This Row],[Order Date]]),MONTH(Orders[[#This Row],[Order Date]]),1) -> 46235 | W39: =IF(Orders[[#This Row],[Order Status]]="Cancelled",Orders[[#This Row],[Net Sales]],0) -> 0
A40: ORD-10039 | B40: 46155 | C40: CUST-1040 | D40: Customer 1147 | E40: East | F40: Bhubaneswar | G40: Shampoo | H40: Beauty | I40: 3 | J40: 499 | K40: 0.1 | L40: COD | M40: Delivered | N40: 46162 | O40: 46159 | P40: =Orders[[#This Row],[Quantity]]*Orders[[#This Row],[Unit Price]] -> 1497 | Q40: =Orders[[#This Row],[Gross Sales]]*Orders[[#This Row],[Discount %]] -> 149.7 | R40: =Orders[[#This Row],[Gross Sales]]-Orders[[#This Row],[Discount Amount]] -> 1347.3 | S40: =IF(Orders[[#This Row],[Actual Delivery Date]]="","",Orders[[#This Row],[Actual Delivery Date]]-Orders[[#This Row],[Order Date]]) -> 4 | T40: =IF(Orders[[#This Row],[Actual Delivery Date]]="","Pending",IF(Orders[[#This Row],[Actual Delivery Date]]<=Orders[[#This Row],[Expected Delivery Date]],"On Time","Late")) -> On Time | U40: =TEXT(Orders[[#This Row],[Order Date]],"mmm") -> May | V40: =DATE(YEAR(Orders[[#This Row],[Order Date]]),MONTH(Orders[[#This Row],[Order Date]]),1) -> 46143 | W40: =IF(Orders[[#This Row],[Order Status]]="Cancelled",Orders[[#This Row],[Net Sales]],0) -> 0
A41: ORD-10040 | B41: 46299 | C41: CUST-1033 | D41: Customer 1213 | E41: West | F41: Ahmedabad | G41: Hoodie | H41: Fashion | I41: 1 | J41: 1999 | K41: 0.05 | L41: Credit Card | M41: Delivered | N41: 46306 | O41: 46301 | P41: =Orders[[#This Row],[Quantity]]*Orders[[#This Row],[Unit Price]] -> 1999 | Q41: =Orders[[#This Row],[Gross Sales]]*Orders[[#This Row],[Discount %]] -> 99.95 | R41: =Orders[[#This Row],[Gross Sales]]-Orders[[#This Row],[Discount Amount]] -> 1899.05 | S41: =IF(Orders[[#This Row],[Actual Delivery Date]]="","",Orders[[#This Row],[Actual Delivery Date]]-Orders[[#This Row],[Order Date]]) -> 2 | T41: =IF(Orders[[#This Row],[Actual Delivery Date]]="","Pending",IF(Orders[[#This Row],[Actual Delivery Date]]<=Orders[[#This Row],[Expected Delivery Date]],"On Time","Late")) -> On Time | U41: =TEXT(Orders[[#This Row],[Order Date]],"mmm") -> Oct | V41: =DATE(YEAR(Orders[[#This Row],[Order Date]]),MONTH(Orders[[#This Row],[Order Date]]),1) -> 46296 | W41: =IF(Orders[[#This Row],[Order Status]]="Cancelled",Orders[[#This Row],[Net Sales]],0) -> 0
A42: ORD-10041 | B42: 46235 | C42: CUST-1295 | D42: Customer 1195 | E42: East | F42: Patna | G42: Cricket Bat | H42: Sports | I42: 1 | J42: 2499 | K42: 0.15 | L42: Net Banking | M42: Returned | N42: 46241 | O42: 46242 | P42: =Orders[[#This Row],[Quantity]]*Orders[[#This Row],[Unit Price]] -> 2499 | Q42: =Orders[[#This Row],[Gross Sales]]*Orders[[#This Row],[Discount %]] -> 374.85 | R42: =Orders[[#This Row],[Gross Sales]]-Orders[[#This Row],[Discount Amount]] -> 2124.15 | S42: =IF(Orders[[#This Row],[Actual Delivery Date]]="","",Orders[[#This Row],[Actual Delivery Date]]-Orders[[#This Row],[Order Date]]) -> 7 | T42: =IF(Orders[[#This Row],[Actual Delivery Date]]="","Pending",IF(Orders[[#This Row],[Actual Delivery Date]]<=Orders[[#This Row],[Expected Delivery Date]],"On Time","Late")) -> Late | U42: =TEXT(Orders[[#This Row],[Order Date]],"mmm") -> Aug | V42: =DATE(YEAR(Orders[[#This Row],[Order Date]]),MONTH(Orders[[#This Row],[Order Date]]),1) -> 46235 | W42: =IF(Orders[[#This Row],[Order Status]]="Cancelled",Orders[[#This Row],[Net Sales]],0) -> 0
A43: ORD-10042 | B43: 46222 | C43: CUST-1113 | D43: Customer 1250 | E43: East | F43: Kolkata | G43: Hoodie | H43: Fashion | I43: 3 | J43: 1999 | K43: 0.15 | L43: COD | M43: Cancelled | N43: 46229 | O43: 46227 | P43: =Orders[[#This Row],[Quantity]]*Orders[[#This Row],[Unit Price]] -> 5997 | Q43: =Orders[[#This Row],[Gross Sales]]*Orders[[#This Row],[Discount %]] -> 899.55 | R43: =Orders[[#This Row],[Gross Sales]]-Orders[[#This Row],[Discount Amount]] -> 5097.45 | S43: =IF(Orders[[#This Row],[Actual Delivery Date]]="","",Orders[[#This Row],[Actual Delivery Date]]-Orders[[#This Row],[Order Date]]) -> 5 | T43: =IF(Orders[[#This Row],[Actual Delivery Date]]="","Pending",IF(Orders[[#This Row],[Actual Delivery Date]]<=Orders[[#This Row],[Expected Delivery Date]],"On Time","Late")) -> On Time | U43: =TEXT(Orders[[#This Row],[Order Date]],"mmm") -> Jul | V43: =DATE(YEAR(Orders[[#This Row],[Order Date]]),MONTH(Orders[[#This Row],[Order Date]]),1) -> 46204 | W43: =IF(Orders[[#This Row],[Order Status]]="Cancelled",Orders[[#This Row],[Net Sales]],0) -> 5097.45
A44: ORD-10043 | B44: 46037 | C44: CUST-1202 | D44: Customer 1289 | E44: West | F44: Ahmedabad | G44: Shampoo | H44: Beauty | I44: 1 | J44: 499 | K44: 0.15 | L44: Credit Card | M44: Returned | N44: 46042 | O44: 46043 | P44: =Orders[[#This Row],[Quantity]]*Orders[[#This Row],[Unit Price]] -> 499 | Q44: =Orders[[#This Row],[Gross Sales]]*Orders[[#This Row],[Discount %]] -> 74.85 | R44: =Orders[[#This Row],[Gross Sales]]-Orders[[#This Row],[Discount Amount]] -> 424.15 | S44: =IF(Orders[[#This Row],[Actual Delivery Date]]="","",Orders[[#This Row],[Actual Delivery Date]]-Orders[[#This Row],[Order Date]]) -> 6 | T44: =IF(Orders[[#This Row],[Actual Delivery Date]]="","Pending",IF(Orders[[#This Row],[Actual Delivery Date]]<=Orders[[#This Row],[Expected Delivery Date]],"On Time","Late")) -> Late | U44: =TEXT(Orders[[#This Row],[Order Date]],"mmm") -> Jan | V44: =DATE(YEAR(Orders[[#This Row],[Order Date]]),MONTH(Orders[[#This Row],[Order Date]]),1) -> 46023 | W44: =IF(Orders[[#This Row],[Order Status]]="Cancelled",Orders[[#This Row],[Net Sales]],0) -> 0
A45: ORD-10044 | B45: 46259 | C45: CUST-1195 | D45: Customer 1143 | E45: South | F45: Bengaluru | G45: Moisturizer | H45: Beauty | I45: 1 | J45: 599 | K45: 0.1 | L45: Net Banking | M45: Delivered | N45: 46262 | O45: 46261 | P45: =Orders[[#This Row],[Quantity]]*Orders[[#This Row],[Unit Price]] -> 599 | Q45: =Orders[[#This Row],[Gross Sales]]*Orders[[#This Row],[Discount %]] -> 59.9 | R45: =Orders[[#This Row],[Gross Sales]]-Orders[[#This Row],[Discount Amount]] -> 539.1 | S45: =IF(Orders[[#This Row],[Actual Delivery Date]]="","",Orders[[#This Row],[Actual Delivery Date]]-Orders[[#This Row],[Order Date]]) -> 2 | T45: =IF(Orders[[#This Row],[Actual Delivery Date]]="","Pending",IF(Orders[[#This Row],[Actual Delivery Date]]<=Orders[[#This Row],[Expected Delivery Date]],"On Time","Late")) -> On Time | U45: =TEXT(Orders[[#This Row],[Order Date]],"mmm") -> Aug | V45: =DATE(YEAR(Orders[[#This Row],[Order Date]]),MONTH(Orders[[#This Row],[Order Date]]),1) -> 46235 | W45: =IF(Orders[[#This Row],[Order Status]]="Cancelled",Orders[[#This Row],[Net Sales]],0) -> 0
A46: ORD-10045 | B46: 46032 | C46: CUST-1021 | D46: Customer 1016 | E46: East | F46: Patna | G46: Power Bank | H46: Electronics | I46: 2 | J46: 1499 | K46: 0 | L46: Debit Card | M46: Delivered | N46: 46039 | O46: 46038 | P46: =Orders[[#This Row],[Quantity]]*Orders[[#This Row],[Unit Price]] -> 2998 | Q46: =Orders[[#This Row],[Gross Sales]]*Orders[[#This Row],[Discount %]] -> 0 | R46: =Orders[[#This Row],[Gross Sales]]-Orders[[#This Row],[Discount Amount]] -> 2998 | S46: =IF(Orders[[#This Row],[Actual Delivery Date]]="","",Orders[[#This Row],[Actual Delivery Date]]-Orders[[#This Row],[Order Date]]) -> 6 | T46: =IF(Orders[[#This Row],[Actual Delivery Date]]="","Pending",IF(Orders[[#This Row],[Actual Delivery Date]]<=Orders[[#This Row],[Expected Delivery Date]],"On Time","Late")) -> On Time | U46: =TEXT(Orders[[#This Row],[Order Date]],"mmm") -> Jan | V46: =DATE(YEAR(Orders[[#This Row],[Order Date]]),MONTH(Orders[[#This Row],[Order Date]]),1) -> 46023 | W46: =IF(Orders[[#This Row],[Order Status]]="Cancelled",Orders[[#This Row],[Net Sales]],0) -> 0
A47: ORD-10046 | B47: 46101 | C47: CUST-1239 | D47: Customer 1132 | E47: West | F47: Pune | G47: USB-C Hub | H47: Electronics | I47: 1 | J47: 1799 | K47: 0.15 | L47: UPI | M47: Pending | N47: 46104 | P47: =Orders[[#This Row],[Quantity]]*Orders[[#This Row],[Unit Price]] -> 1799 | Q47: =Orders[[#This Row],[Gross Sales]]*Orders[[#This Row],[Discount %]] -> 269.85 | R47: =Orders[[#This Row],[Gross Sales]]-Orders[[#This Row],[Discount Amount]] -> 1529.15 | S47: =IF(Orders[[#This Row],[Actual Delivery Date]]="","",Orders[[#This Row],[Actual Delivery Date]]-Orders[[#This Row],[Order Date]]) | T47: =IF(Orders[[#This Row],[Actual Delivery Date]]="","Pending",IF(Orders[[#This Row],[Actual Delivery Date]]<=Orders[[#This Row],[Expected Delivery Date]],"On Time","Late")) -> Pending | U47: =TEXT(Orders[[#This Row],[Order Date]],"mmm") -> Mar | V47: =DATE(YEAR(Orders[[#This Row],[Order Date]]),MONTH(Orders[[#This Row],[Order Date]]),1) -> 46082 | W47: =IF(Orders[[#This Row],[Order Status]]="Cancelled",Orders[[#This Row],[Net Sales]],0) -> 0
A48: ORD-10047 | B48: 46081 | C48: CUST-1295 | D48: Customer 1193 | E48: North | F48: Jaipur | G48: Football | H48: Sports | I48: 3 | J48: 1199 | K48: 0.05 | L48: Debit Card | M48: Delivered | N48: 46087 | O48: 46084 | P48: =Orders[[#This Row],[Quantity]]*Orders[[#This Row],[Unit Price]] -> 3597 | Q48: =Orders[[#This Row],[Gross Sales]]*Orders[[#This Row],[Discount %]] -> 179.85 | R48: =Orders[[#This Row],[Gross Sales]]-Orders[[#This Row],[Discount Amount]] -> 3417.15 | S48: =IF(Orders[[#This Row],[Actual Delivery Date]]="","",Orders[[#This Row],[Actual Delivery Date]]-Orders[[#This Row],[Order Date]]) -> 3 | T48: =IF(Orders[[#This Row],[Actual Delivery Date]]="","Pending",IF(Orders[[#This Row],[Actual Delivery Date]]<=Orders[[#This Row],[Expected Delivery Date]],"On Time","Late")) -> On Time | U48: =TEXT(Orders[[#This Row],[Order Date]],"mmm") -> Feb | V48: =DATE(YEAR(Orders[[#This Row],[Order Date]]),MONTH(Orders[[#This Row],[Order Date]]),1) -> 46054 | W48: =IF(Orders[[#This Row],[Order Status]]="Cancelled",Orders[[#This Row],[Net Sales]],0) -> 0
...

Sheet Analysis
A2: Row Labels | B2: Sum of Net Sales | D2: Order Status | E2: Count of Order ID | G2: Row Labels | H2: Count of Order ID
A3: East | B3: 614373.15 | D3: Returned | E3: 133 | G3: Late | H3: 95
A4: North | B4: 630957.9 | D4: Grand Total | E4: 133 | G4: On Time | H4: 752 | J4: South Percentage | K4: =GETPIVOTDATA("Net Sales",$A$2,"Region","South")/GETPIVOTDATA("Net Sales",$A$2) -> 0.26425385
A5: South | B5: 642685.75 | G5: Pending | H5: 153 | J5: West and North | K5: =K34-K32 -> 0.015617716
A6: West | B6: 544060.35 | G6: Grand Total | H6: 1000 | J6: Sneakers | K6: =GETPIVOTDATA("Cancelled Sales",$A$121,"Product","Sneakers")/GETPIVOTDATA("Net Sales",$A$36,"Product","Sneakers") -> 0.20226415
A7: Grand Total | B7: 2432077.2 | J7: Coffee Maker % | K7: =GETPIVOTDATA("Net Sales",$A$36,"Product","Coffee Maker")/GETPIVOTDATA("Net Sales",$A$36) -> 0.10876481
G8: Completed Orders | H8: =GETPIVOTDATA("Order ID",$G$2,"Delivery Status","On Time")+GETPIVOTDATA("Order ID",$G$2,"Delivery Status","Late") -> 847 | J8: Order fulfillment | K8: =GETPIVOTDATA("Order ID",$D$2,"Order Status","Pending")/GETPIVOTDATA("Order ID",$D$2) -> #REF!
A9: Row Labels | B9: Count of Order ID | D9: Category | E9: Sum of Net Sales | G9: On-Time Orders | H9: =GETPIVOTDATA("Order ID",$G$2,"Delivery Status","On Time") -> 752
A10: East | B10: 257 | D10: Beauty | E10: 239520.05 | G10: On-Time Delivery % | H10: =GETPIVOTDATA("Order ID",$G$2,"Delivery Status","On Time")/(GETPIVOTDATA("Order ID",$G$2,"Delivery Status","On Time")+GETPIVOTDATA("Order ID",$G$2,"Delivery Status","Late")) -> 0.88783943
A11: North | B11: 260 | D11: Electronics | E11: 505171.4
A12: South | B12: 256 | D12: Fashion | E12: 583358.3 | G12: Row Labels | H12: Sum of Delivery Days
A13: West | B13: 227 | D13: Home | E13: 552275.5 | G13: Late | H13: 688
A14: Grand Total | B14: 1000 | D14: Sports | E14: 551751.9 | G14: On Time | H14: 2098
D15: Grand Total | E15: 2432077.2 | G15: Pending | H15: 0
A16: Row Labels | B16: Average of Net Sales | G16: Grand Total | H16: 2786
A17: East | B17: 2390.557 | D17: Row Labels | E17: Sum of Net Sales
A18: North | B18: 2426.7612 | D18: 46023 | E18: 209922.65 | G18: Total Delivery Days | H18: =GETPIVOTDATA("Delivery Days",$G$12,"Delivery Status","On Time")+GETPIVOTDATA("Delivery Days",$G$12,"Delivery Status","Late") -> 2786
A19: South | B19: 2510.4912 | D19: 46054 | E19: 156080.85 | G19: Average Delivery Days | H19: =H18/H8 -> 3.2892562
A20: West | B20: 2396.7416 | D20: 46082 | E20: 185487.95
A21: Grand Total | B21: 2432.0771 | D21: 46113 | E21: 240356.7 | H21: Column Labels
D22: 46143 | E22: 181337.2 | H22: Late | J22: On Time | L22: Pending | N22: Total Average of Delivery Days | O22: Total Count of Order ID
D23: 46174 | E23: 162697.2 | G23: Row Labels | H23: Average of Delivery Days | I23: Count of Order ID | J23: Average of Delivery Days | K23: Count of Order ID | L23: Average of Delivery Days | M23: Count of Order ID
D24: 46204 | E24: 231115.5 | G24: East | H24: 7.0416667 | I24: 24 | J24: 2.746114 | K24: 193 | L24: #DIV/0! | M24: 40 | N24: 3.2211982 | O24: 257
D25: 46235 | E25: 259695.65 | G25: North | H25: 7.2692308 | I25: 26 | J25: 2.7628866 | K25: 194 | L25: #DIV/0! | M25: 40 | N25: 3.2954545 | O25: 260
D26: 46266 | E26: 175760.1 | G26: South | H26: 6.96 | I26: 25 | J26: 2.7421053 | K26: 190 | L26: #DIV/0! | M26: 41 | N26: 3.2325581 | O26: 256
D27: 46296 | E27: 195569.45 | G27: West | H27: 7.8 | I27: 20 | J27: 2.92 | K27: 175 | L27: #DIV/0! | M27: 32 | N27: 3.4205128 | O27: 227
D28: 46327 | E28: 181070.4 | G28: Grand Total | H28: 7.2421053 | I28: 95 | J28: 2.7898936 | K28: 752 | L28: #DIV/0! | M28: 153 | N28: 3.2892562 | O28: 1000
D29: 46357 | E29: 252983.5
D30: Grand Total | E30: 2432077.1 | G30: Region | H30: On-Time Orders | I30: Late Orders | J30: Completed Orders | K30: On-Time Delivery %
G31: East | H31: =GETPIVOTDATA("Count of Order ID",$G$21,"Region","East","Delivery Status","On Time") -> 193 | I31: =GETPIVOTDATA("Count of Order ID",$G$21,"Region","East","Delivery Status","Late") -> 24 | J31: =H31+I31 -> 217 | K31: =H31/J31 -> 0.88940092
G32: North | H32: =GETPIVOTDATA("Count of Order ID",$G$21,"Region","North","Delivery Status","On Time") -> 194 | I32: =GETPIVOTDATA("Count of Order ID",$G$21,"Region","North","Delivery Status","Late") -> 26 | J32: =H32+I32 -> 220 | K32: =H32/J32 -> 0.88181818
G33: South | H33: =GETPIVOTDATA("Count of Order ID",$G$21,"Region","South","Delivery Status","On Time") -> 190 | I33: =GETPIVOTDATA("Count of Order ID",$G$21,"Region","South","Delivery Status","Late") -> 25 | J33: =H33+I33 -> 215 | K33: =H33/J33 -> 0.88372093
G34: West | H34: =GETPIVOTDATA("Count of Order ID",$G$21,"Region","West","Delivery Status","On Time") -> 175 | I34: =GETPIVOTDATA("Count of Order ID",$G$21,"Region","West","Delivery Status","Late") -> 20 | J34: =H34+I34 -> 195 | K34: =H34/J34 -> 0.8974359
G35: Overall On-Time Delivery % | H35: =(SUM(H31:H34))/(SUM(J31:J34)) -> 0.88783943
A36: Product | B36: Sum of Net Sales | D36: Count of Order ID | E36: Column Labels
A37: Coffee Maker | B37: 264524.4 | D37: Row Labels | E37: Cancelled | F37: Delivered | G37: Pending | H37: Returned | I37: Grand Total | J37: Cancellation Rate
A38: Running Shoes | B38: 221692.8 | D38: Backpack | E38: 3 | F38: 19 | G38: 6 | H38: 7 | I38: 35 | J38: =E38/I38 -> 0.085714286
A39: Sneakers | B39: 198683.75 | D39: Bedsheet Set | E39: 4 | F39: 21 | G39: 6 | H39: 4 | I39: 35 | J39: =E39/I39 -> 0.11428571
A40: Cricket Bat | B40: 174305.25 | D40: Bluetooth Speaker | E40: 8 | F40: 27 | G40: 9 | H40: 6 | I40: 50 | J40: =E40/I40 -> 0.16
A41: Bluetooth Speaker | B41: 160019.95 | D41: Coffee Maker | E41: 2 | F41: 29 | G41: 9 | H41: 4 | I41: 44 | J41: =E41/I41 -> 0.045454545
...

Sheet Dashboard
A1: SALES AND OPERATIONS DATA 2026
A2: TOTAL REVENUE | C2: TOTAL ORDERS | E2: AVERAGE ORDER VALUE | G2: ON TIME DELIVERY | I2: CANCELLATION RATE | K2: AVERAGE DELIVERY DAYS
A3: =GETPIVOTDATA("Net Sales",Analysis!$A$2) -> 2432077.2 | C3: =GETPIVOTDATA("Order ID",Analysis!$A$9) -> 1000 | E3: =GETPIVOTDATA("Net Sales",Analysis!$A$16) -> 2432.0771 | G3: =Analysis!H10 -> 0.88783943 | I3: =Analysis!E65 -> 0.131 | K3: =Analysis!H19 -> 3.2892562
A82: KEY BUSINESS INSIGHTS
A84: ● South leads regional sales, contributing 26.43% of total revenue.
A86: ● Delivery performance is relatively consistent across regions;
A87: the West–North gap is only 1.56 percentage points.
A89: ● Sneakers have ₹40.2K in cancelled sales, equal to 20.23%
A90: of their net sales — a potential area for investigation.
A92: ● Coffee Maker is the top-revenue product, contributing 10.88%
A93: of total net sales.
A95: ● 15.30% of orders remain pending, indicating a significant
A96: fulfillment backlog.
